Workbook
Name CertifiedValue: 'Certified Value'!$C$4
Name DegFree: 'Ratio Analysis'!$F$189
Name fef: 'Certified Value'!$C$4
Name Intercept: 'Std Analysis'!$I$5
Name MeanRatio: 'Ratio Analysis'!$F$187
Name RatioData: 'Ratio Data'!$A$1:$G$1412
Name RCodeOptions: #REF!
Name Regdf: 'Std Analysis'!$I$7
Name SConc: 'Standards Data'!$D$2:$D$200
Name ScottData: 'Vendor Data'!$D$2:$D$9997
Name Slope: 'Std Analysis'!$I$3
Name SRatio: 'Standards Data'!$C$2:$C$200
Name StdUnc: 'Ratio Analysis'!$F$188
Name uintercept: 'Std Analysis'!$I$6
Name umb: 'Std Analysis'!$I$8
Name uslope: 'Std Analysis'!$I$4

Sheet Ratio Data
A1: SampleID | B1: SampleNo | C1: Ratio | D1: LSSet | E1: BreakSet | F1: Day | G1: Port | H1: ValueG | I1: Test | J1: 11/25/2024 - CEC checked/amended original file after reviewing raw data, now addresses everythign in "…-marked.xls"
A2: 48-I-05 | B2: 5 | C2: 0.98215122 | D2: 26 | E2: 4 | F2: 3 | G2: 2 | H2: =IF(ISBLANK(C2),"",C2*$L$13) -> 5.047634 | I2: =IF(ISNUMBER(H2),IF(ABS(H2-$L$14)>$M$16,"OUT",""),"") | J2: SampleID = SRM designation (eg., 41-M-05)
A3: 48-I-05 | B3: 5 | C3: 0.98314714 | D3: 27 | E3: 4 | F3: 3 | G3: 2 | H3: =IF(ISBLANK(C3),"",C3*$L$13) -> 5.0527523 | I3: =IF(ISNUMBER(H3),IF(ABS(H3-$L$14)>$M$16,"OUT",""),"") | J3: SampleNo = number associated with sampleID (e.g., 5)
A4: 48-I-05 | B4: 5 | C4: 0.98295776 | D4: 29 | E4: 4 | F4: 3 | G4: 2 | H4: =IF(ISBLANK(C4),"",C4*$L$13) -> 5.051779 | I4: =IF(ISNUMBER(H4),IF(ABS(H4-$L$14)>$M$16,"OUT",""),"") | J4: Ratio = ratio of response to LS
A5: 48-I-05 | B5: 5 | C5: 0.9826283 | D5: 31 | E5: 4 | F5: 3 | G5: 2 | H5: =IF(ISBLANK(C5),"",C5*$L$13) -> 5.0500858 | I5: =IF(ISNUMBER(H5),IF(ABS(H5-$L$14)>$M$16,"OUT",""),"") | J5: LSSet = all ratios measured between LS measurements are a "set" and are assigned the same number (1,2,3…)
A6: 48-I-05 | B6: 5 | C6: 0.97903258 | D6: 186 | E6: 24 | F6: 17 | G6: 3 | H6: =IF(ISBLANK(C6),"",C6*$L$13) -> 5.0316061 | I6: =IF(ISNUMBER(H6),IF(ABS(H6-$L$14)>$M$16,"OUT",""),"") | J6: BreakSet = all ratios measured without significant interruption (COGAS setup)
A7: 48-I-05 | B7: 5 | C7: 0.97963239 | D7: 187 | E7: 24 | F7: 17 | G7: 3 | H7: =IF(ISBLANK(C7),"",C7*$L$13) -> 5.0346888 | I7: =IF(ISNUMBER(H7),IF(ABS(H7-$L$14)>$M$16,"OUT",""),"") | J7: Day = All measurements taken on the same day
A8: 48-I-05 | B8: 5 | C8: 0.98014634 | D8: 190 | E8: 24 | F8: 17 | G8: 3 | H8: =IF(ISBLANK(C8),"",C8*$L$13) -> 5.0373301 | I8: =IF(ISNUMBER(H8),IF(ABS(H8-$L$14)>$M$16,"OUT",""),"") | J8: Port = COGAS Port number
A9: 48-I-05 | B9: 5 | C9: 0.97969228 | D9: 192 | E9: 24 | F9: 17 | G9: 3 | H9: =IF(ISBLANK(C9),"",C9*$L$13) -> 5.0349965 | I9: =IF(ISNUMBER(H9),IF(ABS(H9-$L$14)>$M$16,"OUT",""),"")
A10: 48-I-06 | B10: 6 | C10: 0.97303074 | D10: 18 | E10: 3 | F10: 2 | G10: 2 | H10: =IF(ISBLANK(C10),"",C10*$L$13) -> 5.0007605 | I10: =IF(ISNUMBER(H10),IF(ABS(H10-$L$14)>$M$16,"OUT",""),"") | J10: Named Range: RatioData
A11: 48-I-06 | B11: 6 | C11: 0.97390929 | D11: 19 | E11: 3 | F11: 2 | G11: 2 | H11: =IF(ISBLANK(C11),"",C11*$L$13) -> 5.0052757 | I11: =IF(ISNUMBER(H11),IF(ABS(H11-$L$14)>$M$16,"OUT",""),"")
A12: 48-I-06 | B12: 6 | C12: 0.97377384 | D12: 21 | E12: 3 | F12: 2 | G12: 2 | H12: =IF(ISBLANK(C12),"",C12*$L$13) -> 5.0045795 | I12: =IF(ISNUMBER(H12),IF(ABS(H12-$L$14)>$M$16,"OUT",""),"") | L12: R Values | M12: Low | N12: High
A13: 48-I-06 | B13: 6 | C13: 0.97369615 | D13: 23 | E13: 3 | F13: 2 | G13: 2 | H13: =IF(ISBLANK(C13),"",C13*$L$13) -> 5.0041802 | I13: =IF(ISNUMBER(H13),IF(ABS(H13-$L$14)>$M$16,"OUT",""),"") | J13: Lot Standard | L13: ='Std Analysis'!L5 -> 5.1393653
A14: 48-I-06 | B14: 6 | C14: 0.9733498 | D14: 218 | E14: 28 | F14: 19 | G14: 5 | H14: =IF(ISBLANK(C14),"",C14*$L$13) -> 5.0024002 | I14: =IF(ISNUMBER(H14),IF(ABS(H14-$L$14)>$M$16,"OUT",""),"") | J14: =IF('Certified Value'!C43<>0,'Certified Value'!B43,'Certified Value'!B42) -> Certified Value (R Code): | L14: =IF('Certified Value'!C43<>0,'Certified Value'!C43,'Certified Value'!C42) -> 5.0422566 | M14: =L14-M16 -> 4.9905352 | N14: =L14+M16 -> 5.093978
A15: 48-I-06 | B15: 6 | C15: 0.97391421 | D15: 219 | E15: 28 | F15: 19 | G15: 5 | H15: =IF(ISBLANK(C15),"",C15*$L$13) -> 5.0053009 | I15: =IF(ISNUMBER(H15),IF(ABS(H15-$L$14)>$M$16,"OUT",""),"") | J15: Uncertainty | L15: =IF('Certified Value'!E43<>0,'Certified Value'!E43,'Certified Value'!E42) -> 0.064651718
A16: 48-I-06 | B16: 6 | C16: 0.97403158 | D16: 221 | E16: 28 | F16: 19 | G16: 5 | H16: =IF(ISBLANK(C16),"",C16*$L$13) -> 5.0059042 | I16: =IF(ISNUMBER(H16),IF(ABS(H16-$L$14)>$M$16,"OUT",""),"") | J16: Allowed coverage | L16: =80% -> 0.8 | M16: =L15*L16 -> 0.051721374
A17: 48-I-06 | B17: 6 | C17: 0.97404622 | D17: 223 | E17: 28 | F17: 19 | G17: 5 | H17: =IF(ISBLANK(C17),"",C17*$L$13) -> 5.0059794 | I17: =IF(ISNUMBER(H17),IF(ABS(H17-$L$14)>$M$16,"OUT",""),"") | J17: Number of points = | L17: =COUNT(C2:C912) -> 472
A18: 48-I-07 | B18: 7 | C18: 0.9874132 | D18: 17 | E18: 3 | F18: 2 | G18: 3 | H18: =IF(ISBLANK(C18),"",C18*$L$13) -> 5.0746772 | I18: =IF(ISNUMBER(H18),IF(ABS(H18-$L$14)>$M$16,"OUT",""),"")
A19: 48-I-07 | B19: 7 | C19: 0.98670394 | D19: 19 | E19: 3 | F19: 2 | G19: 3 | H19: =IF(ISBLANK(C19),"",C19*$L$13) -> 5.071032 | I19: =IF(ISNUMBER(H19),IF(ABS(H19-$L$14)>$M$16,"OUT",""),"")
A20: 48-I-07 | B20: 7 | C20: 0.98676596 | D20: 22 | E20: 3 | F20: 2 | G20: 3 | H20: =IF(ISBLANK(C20),"",C20*$L$13) -> 5.0713508 | I20: =IF(ISNUMBER(H20),IF(ABS(H20-$L$14)>$M$16,"OUT",""),"") | K20: Put SRM information here
A21: 48-I-07 | B21: 7 | C21: 0.9868614 | D21: 23 | E21: 3 | F21: 2 | G21: 3 | H21: =IF(ISBLANK(C21),"",C21*$L$13) -> 5.0718413 | I21: =IF(ISNUMBER(H21),IF(ABS(H21-$L$14)>$M$16,"OUT",""),"") | J21: SRM# | K21: SRM 2627a | Q21: <---THIS WILL PREPARE THE SPREADSHEETS FOR NEW DATA
A22: 48-I-07 | B22: 7 | C22: 0.98661766 | D22: 238 | E22: 31 | F22: 22 | G22: 4 | H22: =IF(ISBLANK(C22),"",C22*$L$13) -> 5.0705886 | I22: =IF(ISNUMBER(H22),IF(ABS(H22-$L$14)>$M$16,"OUT",""),"") | J22: Nominal | K22: 5 ppm NO in N2 | Q22: <--DO NOT USE ON A SPREEDSHEET YOU HAVE NOT SAVED
A23: 48-I-07 | B23: 7 | C23: 0.98515604 | D23: 239 | E23: 31 | F23: 22 | G23: 4 | H23: =IF(ISBLANK(C23),"",C23*$L$13) -> 5.0630768 | I23: =IF(ISNUMBER(H23),IF(ABS(H23-$L$14)>$M$16,"OUT",""),"") | J23: Units | K23: ppm
A24: 48-I-07 | B24: 7 | C24: 0.98640896 | D24: 240 | E24: 31 | F24: 22 | G24: 4 | H24: =IF(ISBLANK(C24),"",C24*$L$13) -> 5.069516 | I24: =IF(ISNUMBER(H24),IF(ABS(H24-$L$14)>$M$16,"OUT",""),"")
A25: 48-I-07 | B25: 7 | C25: 0.98539672 | D25: 242 | E25: 31 | F25: 22 | G25: 4 | H25: =IF(ISBLANK(C25),"",C25*$L$13) -> 5.0643138 | I25: =IF(ISNUMBER(H25),IF(ABS(H25-$L$14)>$M$16,"OUT",""),"") | J25: Polynomial = | K25: 1
A26: 48-I-08 | B26: 8 | C26: 0.96748881 | D26: 26 | E26: 4 | F26: 3 | G26: 7 | H26: =IF(ISBLANK(C26),"",C26*$L$13) -> 4.9722784 | I26: =IF(ISNUMBER(H26),IF(ABS(H26-$L$14)>$M$16,"OUT",""),"") -> OUT | J26: Interations = | K26: 5000
A27: 48-I-08 | B27: 8 | C27: 0.96811936 | D27: 28 | E27: 4 | F27: 3 | G27: 7 | H27: =IF(ISBLANK(C27),"",C27*$L$13) -> 4.9755191 | I27: =IF(ISNUMBER(H27),IF(ABS(H27-$L$14)>$M$16,"OUT",""),"") -> OUT | J27: Cores = | K27: 4
A28: 48-I-08 | B28: 8 | C28: 0.96763822 | D28: 30 | E28: 4 | F28: 3 | G28: 7 | H28: =IF(ISBLANK(C28),"",C28*$L$13) -> 4.9730463 | I28: =IF(ISNUMBER(H28),IF(ABS(H28-$L$14)>$M$16,"OUT",""),"") -> OUT
A29: 48-I-08 | B29: 8 | C29: 0.96729551 | D29: 32 | E29: 4 | F29: 3 | G29: 7 | H29: =IF(ISBLANK(C29),"",C29*$L$13) -> 4.971285 | I29: =IF(ISNUMBER(H29),IF(ABS(H29-$L$14)>$M$16,"OUT",""),"") -> OUT
A30: 48-I-08 | B30: 8 | C30: 0.96472972 | D30: 226 | E30: 29 | F30: 20 | G30: 5 | H30: =IF(ISBLANK(C30),"",C30*$L$13) -> 4.9580985 | I30: =IF(ISNUMBER(H30),IF(ABS(H30-$L$14)>$M$16,"OUT",""),"") -> OUT | J30: Before sending your data to Christina, please format the filename as follows:
A31: 48-I-08 | B31: 8 | C31: 0.96470449 | D31: 227 | E31: 29 | F31: 20 | G31: 5 | H31: =IF(ISBLANK(C31),"",C31*$L$13) -> 4.9579688 | I31: =IF(ISNUMBER(H31),IF(ABS(H31-$L$14)>$M$16,"OUT",""),"") -> OUT | J31: [SRM number]_[Series]_[your initials]_[component - only for NO/NOx].xls
A32: 48-I-08 | B32: 8 | C32: 0.9641142 | D32: 229 | E32: 29 | F32: 20 | G32: 5 | H32: =IF(ISBLANK(C32),"",C32*$L$13) -> 4.9549351 | I32: =IF(ISNUMBER(H32),IF(ABS(H32-$L$14)>$M$16,"OUT",""),"") -> OUT
A33: 48-I-08 | B33: 8 | C33: 0.96472483 | D33: 231 | E33: 29 | F33: 20 | G33: 5 | H33: =IF(ISBLANK(C33),"",C33*$L$13) -> 4.9580733 | I33: =IF(ISNUMBER(H33),IF(ABS(H33-$L$14)>$M$16,"OUT",""),"") -> OUT | J33: Examples: | K33: SRM1687b_SeriesM_CEL_NO.xls
A34: 48-I-09 | B34: 9 | C34: 0.97796945 | D34: 49 | E34: 7 | F34: 5 | G34: 3 | H34: =IF(ISBLANK(C34),"",C34*$L$13) -> 5.0261423 | I34: =IF(ISNUMBER(H34),IF(ABS(H34-$L$14)>$M$16,"OUT",""),"") | J34: No spaces! | K34: SRM1693a_SeriesN_MEK.xls
A35: 48-I-09 | B35: 9 | C35: 0.97795725 | D35: 51 | E35: 7 | F35: 5 | G35: 3 | H35: =IF(ISBLANK(C35),"",C35*$L$13) -> 5.0260796 | I35: =IF(ISNUMBER(H35),IF(ABS(H35-$L$14)>$M$16,"OUT",""),"")
A36: 48-I-09 | B36: 9 | C36: 0.97709112 | D36: 54 | E36: 7 | F36: 5 | G36: 3 | H36: =IF(ISBLANK(C36),"",C36*$L$13) -> 5.0216282 | I36: =IF(ISNUMBER(H36),IF(ABS(H36-$L$14)>$M$16,"OUT",""),"") | J36: 48-I-13 | K36: 13 | L36: 0.94251271 | M36: 33 | N36: 5 | O36: 4 | P36: 3
A37: 48-I-09 | B37: 9 | C37: 0.97770176 | D37: 55 | E37: 7 | F37: 5 | G37: 3 | H37: =IF(ISBLANK(C37),"",C37*$L$13) -> 5.0247666 | I37: =IF(ISNUMBER(H37),IF(ABS(H37-$L$14)>$M$16,"OUT",""),"") | J37: 48-I-13 | K37: 13 | L37: 0.94203421 | M37: 35 | N37: 5 | O37: 4 | P37: 3
A38: 48-I-09 | B38: 9 | C38: 0.97713026 | D38: 145 | E38: 19 | F38: 14 | G38: 4 | H38: =IF(ISBLANK(C38),"",C38*$L$13) -> 5.0218294 | I38: =IF(ISNUMBER(H38),IF(ABS(H38-$L$14)>$M$16,"OUT",""),"") | J38: 48-I-13 | K38: 13 | L38: 0.94222086 | M38: 38 | N38: 5 | O38: 4 | P38: 3
A39: 48-I-09 | B39: 9 | C39: 0.97647701 | D39: 148 | E39: 19 | F39: 14 | G39: 4 | H39: =IF(ISBLANK(C39),"",C39*$L$13) -> 5.0184721 | I39: =IF(ISNUMBER(H39),IF(ABS(H39-$L$14)>$M$16,"OUT",""),"") | J39: 48-I-13 | K39: 13 | L39: 0.94250251 | M39: 39 | N39: 5 | O39: 4 | P39: 3
A40: 48-I-09 | B40: 9 | C40: 0.97750378 | D40: 149 | E40: 19 | F40: 14 | G40: 4 | H40: =IF(ISBLANK(C40),"",C40*$L$13) -> 5.0237491 | I40: =IF(ISNUMBER(H40),IF(ABS(H40-$L$14)>$M$16,"OUT",""),"") | J40: 48-I-13 | K40: 13 | L40: 0.94163917 | M40: 209 | N40: 27 | O40: 19 | P40: 2
...

Sheet Vendor Data
A1: SampleID | B1: SampleNo | C1: CylinderNo | D1: VendorRatio | F1: Average | G1: Stdev | H1: %rel
A2: 48-I-05 | B2: 5 | C2: FF57833 | D2: 0.97614474 | E2: Vendor | F2: =AVERAGE(ScottData) -> 0.98271256 | G2: =STDEV(ScottData) -> 0.0039476508 | H2: =G2/F2 -> 0.0040170961
A3: 48-I-05 | B3: 5 | C3: FF57833 | D3: 0.97626275 | E3: NIST | F3: =AVERAGE('Ratio Data'!C2:C10000) -> 0.9805811 | G3: =STDEV('Ratio Data'!C2:C10000) -> 0.0064671357 | H3: =G3/F3 -> 0.0065952074
A4: 48-I-05 | B4: 5 | C4: FF57833 | D4: 0.97850552 | E4: difference | F4: =(F2-F3)/F3 -> 0.0021736676
A5: 48-I-06 | B5: 6 | C5: FF58537 | D5: 0.98416422
A6: 48-I-06 | B6: 6 | C6: FF58537 | D6: 0.98533988
A7: 48-I-06 | B7: 6 | C7: FF58537 | D7: 0.98702318
A8: 48-I-07 | B8: 7 | C8: FF58526 | D8: 0.98108749
A9: 48-I-07 | B9: 7 | C9: FF58526 | D9: 0.98183524
A10: 48-I-07 | B10: 7 | C10: FF58526 | D10: 0.98228221
A11: 48-I-08 | B11: 8 | C11: FF58516 | D11: 0.98115998
A12: 48-I-08 | B12: 8 | C12: FF58516 | D12: 0.98209584
A13: 48-I-08 | B13: 8 | C13: FF58516 | D13: 0.98299574
A14: 48-I-09 | B14: 9 | C14: FF57814 | D14: 0.97466626
A15: 48-I-09 | B15: 9 | C15: FF57814 | D15: 0.97675102
A16: 48-I-09 | B16: 9 | C16: FF57814 | D16: 0.9769375
... A178: 48-I-64 | B178: 64 | C178: FF57826 | D178: 0.98338314

Sheet Standards Data
A1: StandardID | B1: StandardNo | C1: SRatio | D1: SConc | E1: Sunc | F1: Suncert | G1: Named Ranges: "SConc" and "SRatio" | K1: StandardNo | L1: StandardNo | M1: StandardNo | N1: StandardNo | O1: StandardNo | P1: StandardNo | Q1: StandardNo | R1: StandardNo | S1: StandardNo | T1: StandardNo | AB1: StandardNo | AC1: StandardID
A2: FF38000 | B2: 1 | C2: 0.77643067 | D2: 4.0069 | E2: 0.0031 | F2: =IF(ISBLANK(B2),"",IF(ISNUMBER($K$10),D2*$K$10,E2)) -> 0.0080138 | G2: Count = | H2: =COUNT(SConc) -> 46 | K2: 1 | L2: 2 | M2: 3 | N2: 4 | O2: 5 | P2: 6 | Q2: 7 | R2: 8 | S2: 9 | T2: 10 | AB2: =B2 -> 1 | AC2: =A2 -> FF38000
A3: FF38000 | B3: 1 | C3: 0.77666334 | D3: 4.0069 | E3: 0.0031 | F3: =IF(ISBLANK(B3),"",IF(ISNUMBER($K$10),D3*$K$10,E3)) -> 0.0080138 | G3: Max N = | H3: 1 | J3: StandardID | K3: =VLOOKUP(K2,$AB$2:$AC$200,2,FALSE) -> FF38000 | L3: =VLOOKUP(L2,$AB$2:$AC$200,2,FALSE) -> FF38022 | M3: =VLOOKUP(M2,$AB$2:$AC$200,2,FALSE) -> FF18162 | N3: =VLOOKUP(N2,$AB$2:$AC$200,2,FALSE) -> CAL016209 | O3: =VLOOKUP(O2,$AB$2:$AC$200,2,FALSE) -> #N/A | P3: =VLOOKUP(P2,$AB$2:$AC$200,2,FALSE) -> #N/A | Q3: =VLOOKUP(Q2,$AB$2:$AC$200,2,FALSE) -> #N/A | R3: =VLOOKUP(R2,$AB$2:$AC$200,2,FALSE) -> #N/A | ... T3: =VLOOKUP(T2,$AB$2:$AC$200,2,FALSE) -> #N/A | AB3: =B3 -> 1 | AC3: =A3 -> FF38000
A4: FF38000 | B4: 1 | C4: 0.7765254 | D4: 4.0069 | E4: 0.0031 | F4: =IF(ISBLANK(B4),"",IF(ISNUMBER($K$10),D4*$K$10,E4)) -> 0.0080138 | J4: Average | K4: =DAVERAGE($A$1:$D$200,3,K1:K2) -> 0.77623406 | L4: =DAVERAGE($A$1:$D$200,3,L1:L2) -> 0.9632245 | M4: =DAVERAGE($A$1:$D$200,3,M1:M2) -> 1.178333 | N4: =DAVERAGE($A$1:$D$200,3,N1:N2) -> 1.7726021 | O4: =DAVERAGE($A$1:$D$200,3,O1:O2) -> #DIV/0! | P4: =DAVERAGE($A$1:$D$200,3,P1:P2) -> #DIV/0! | Q4: =DAVERAGE($A$1:$D$200,3,Q1:Q2) -> #DIV/0! | R4: =DAVERAGE($A$1:$D$200,3,R1:R2) -> #DIV/0! | ... T4: =DAVERAGE($A$1:$D$200,3,T1:T2) -> #DIV/0! | AB4: =B4 -> 1 | AC4: =A4 -> FF38000
A5: FF38000 | B5: 1 | C5: 0.77606013 | D5: 4.0069 | E5: 0.0031 | F5: =IF(ISBLANK(B5),"",IF(ISNUMBER($K$10),D5*$K$10,E5)) -> 0.0080138 | J5: StdErr | K5: =DSTDEV($A$1:$D$200,3,K1:K2)/SQRT(MIN(DCOUNT($A$1:$D$200,3,K1:K2),$H$3)) -> 0.00040122745 | L5: =DSTDEV($A$1:$D$200,3,L1:L2)/SQRT(MIN(DCOUNT($A$1:$D$200,3,L1:L2),$H$3)) -> 0.0006459443 | M5: =DSTDEV($A$1:$D$200,3,M1:M2)/SQRT(MIN(DCOUNT($A$1:$D$200,3,M1:M2),$H$3)) -> 0.00053153008 | N5: =DSTDEV($A$1:$D$200,3,N1:N2)/SQRT(MIN(DCOUNT($A$1:$D$200,3,N1:N2),$H$3)) -> 0.00051164668 | O5: =DSTDEV($A$1:$D$200,3,O1:O2)/SQRT(MIN(DCOUNT($A$1:$D$200,3,O1:O2),$H$3)) -> #DIV/0! | P5: =DSTDEV($A$1:$D$200,3,P1:P2)/SQRT(MIN(DCOUNT($A$1:$D$200,3,P1:P2),$H$3)) -> #DIV/0! | Q5: =DSTDEV($A$1:$D$200,3,Q1:Q2)/SQRT(MIN(DCOUNT($A$1:$D$200,3,Q1:Q2),$H$3)) -> #DIV/0! | R5: =DSTDEV($A$1:$D$200,3,R1:R2)/SQRT(MIN(DCOUNT($A$1:$D$200,3,R1:R2),$H$3)) -> #DIV/0! | ... T5: =DSTDEV($A$1:$D$200,3,T1:T2)/SQRT(MIN(DCOUNT($A$1:$D$200,3,T1:T2),$H$3)) -> #DIV/0! | AB5: =B5 -> 1 | AC5: =A5 -> FF38000
A6: FF38000 | B6: 1 | C6: 0.77579973 | D6: 4.0069 | E6: 0.0031 | F6: =IF(ISBLANK(B6),"",IF(ISNUMBER($K$10),D6*$K$10,E6)) -> 0.0080138 | K6: =K5/K4 -> 0.00051688977 | L6: =L5/L4 -> 0.00067060618 | M6: =M5/M4 -> 0.00045108648 | N6: =N5/N4 -> 0.00028864158 | O6: =O5/O4 -> #DIV/0! | P6: =P5/P4 -> #DIV/0! | AB6: =B6 -> 1 | AC6: =A6 -> FF38000
A7: FF38000 | B7: 1 | C7: 0.77670638 | D7: 4.0069 | E7: 0.0031 | F7: =IF(ISBLANK(B7),"",IF(ISNUMBER($K$10),D7*$K$10,E7)) -> 0.0080138 | J7: Conc | K7: =VLOOKUP(K2,$B$1:$E$200,3,FALSE) -> 4.0069 | L7: =VLOOKUP(L2,$B$1:$E$200,3,FALSE) -> 4.972 | M7: =VLOOKUP(M2,$B$1:$E$200,3,FALSE) -> 6.036 | N7: =VLOOKUP(N2,$B$1:$E$200,3,FALSE) -> 9.007 | O7: =VLOOKUP(O2,$B$1:$E$200,3,FALSE) -> #N/A | P7: =VLOOKUP(P2,$B$1:$E$200,3,FALSE) -> #N/A | Q7: =VLOOKUP(Q2,$B$1:$E$200,3,FALSE) -> #N/A | R7: =VLOOKUP(R2,$B$1:$E$200,3,FALSE) -> #N/A | ... T7: =VLOOKUP(T2,$B$1:$E$200,3,FALSE) -> #N/A | AB7: =B7 -> 1 | AC7: =A7 -> FF38000
A8: FF38000 | B8: 1 | C8: 0.77642811 | D8: 4.0069 | E8: 0.0031 | F8: =IF(ISBLANK(B8),"",IF(ISNUMBER($K$10),D8*$K$10,E8)) -> 0.0080138 | J8: uncert | K8: =IF(ISBLANK($K$10),VLOOKUP(K2,$B$1:$E$200,4,FALSE),$K$10*K7) -> 0.0080138 | L8: =IF(ISBLANK($K$10),VLOOKUP(L2,$B$1:$E$200,4,FALSE),$K$10*L7) -> 0.009944 | M8: =IF(ISBLANK($K$10),VLOOKUP(M2,$B$1:$E$200,4,FALSE),$K$10*M7) -> 0.012072 | N8: =IF(ISBLANK($K$10),VLOOKUP(N2,$B$1:$E$200,4,FALSE),$K$10*N7) -> 0.018014 | O8: =IF(ISBLANK($K$10),VLOOKUP(O2,$B$1:$E$200,4,FALSE),$K$10*O7) -> #N/A | P8: =IF(ISBLANK($K$10),VLOOKUP(P2,$B$1:$E$200,4,FALSE),$K$10*P7) -> #N/A | Q8: =IF(ISBLANK($K$10),VLOOKUP(Q2,$B$1:$E$200,4,FALSE),$K$10*Q7) -> #N/A | R8: =IF(ISBLANK($K$10),VLOOKUP(R2,$B$1:$E$200,4,FALSE),$K$10*R7) -> #N/A | ... T8: =IF(ISBLANK($K$10),VLOOKUP(T2,$B$1:$E$200,4,FALSE),$K$10*T7) -> #N/A | AB8: =B8 -> 1 | AC8: =A8 -> FF38000
A9: FF38000 | B9: 1 | C9: 0.77590451 | D9: 4.0069 | E9: 0.0031 | F9: =IF(ISBLANK(B9),"",IF(ISNUMBER($K$10),D9*$K$10,E9)) -> 0.0080138 | K9: =K8/K7 -> 0.002 | L9: =L8/L7 -> 0.002 | M9: =M8/M7 -> 0.002 | N9: =N8/N7 -> 0.002 | O9: =O8/O7 -> #N/A | P9: =P8/P7 -> #N/A | Q9: =Q8/Q7 -> #N/A | R9: =R8/R7 -> #N/A | ... T9: =T8/T7 -> #N/A | AB9: =B9 -> 1 | AC9: =A9 -> FF38000
A10: FF38000 | B10: 1 | C10: 0.77614823 | D10: 4.0069 | E10: 0.0031 | F10: =IF(ISBLANK(B10),"",IF(ISNUMBER($K$10),D10*$K$10,E10)) -> 0.0080138 | I10: PSM Uncertainty = | K10: 0.002 | L10: <--overrides standards uncertainty column in table to left | AB10: =B10 -> 1 | AC10: =A10 -> FF38000
A11: FF38000 | B11: 1 | C11: 0.77653265 | D11: 4.0069 | E11: 0.0031 | F11: =IF(ISBLANK(B11),"",IF(ISNUMBER($K$10),D11*$K$10,E11)) -> 0.0080138 | AB11: =B11 -> 1 | AC11: =A11 -> FF38000
A12: FF38000 | B12: 1 | C12: 0.77625744 | D12: 4.0069 | E12: 0.0031 | F12: =IF(ISBLANK(B12),"",IF(ISNUMBER($K$10),D12*$K$10,E12)) -> 0.0080138 | J12: Number PSMs in order from lowest to highest concentration | AB12: =B12 -> 1 | AC12: =A12 -> FF38000
A13: FF38000 | B13: 1 | C13: 0.77535219 | D13: 4.0069 | E13: 0.0031 | F13: =IF(ISBLANK(B13),"",IF(ISNUMBER($K$10),D13*$K$10,E13)) -> 0.0080138 | J13: Make sure Sunc is given as standard uncertainty (k = 1)! | AB13: =B13 -> 1 | AC13: =A13 -> FF38000
A14: FF38022 | B14: 2 | C14: 0.96318896 | D14: 4.972 | E14: 0.005 | F14: =IF(ISBLANK(B14),"",IF(ISNUMBER($K$10),D14*$K$10,E14)) -> 0.009944 | AB14: =B14 -> 2 | AC14: =A14 -> FF38022
A15: FF38022 | B15: 2 | C15: 0.96286192 | D15: 4.972 | E15: 0.005 | F15: =IF(ISBLANK(B15),"",IF(ISNUMBER($K$10),D15*$K$10,E15)) -> 0.009944 | J15: Std# | K15: Conc | L15: uncert | M15: Ratio | N15: uncert | AB15: =B15 -> 2 | AC15: =A15 -> FF38022
A16: FF38022 | B16: 2 | C16: 0.9624756 | D16: 4.972 | E16: 0.005 | F16: =IF(ISBLANK(B16),"",IF(ISNUMBER($K$10),D16*$K$10,E16)) -> 0.009944 | J16: 1 | K16: =IF(ISERROR(K7),"",K7) -> 4.0069 | L16: =IF(ISERROR(K8),"",K8) -> 0.0080138 | M16: =IF(ISERROR(K4),"",K4) -> 0.77623406 | N16: =IF(ISERROR(K5),"",K5) -> 0.00040122745 | AB16: =B16 -> 2 | AC16: =A16 -> FF38022
A17: FF38022 | B17: 2 | C17: 0.96270312 | D17: 4.972 | E17: 0.005 | F17: =IF(ISBLANK(B17),"",IF(ISNUMBER($K$10),D17*$K$10,E17)) -> 0.009944 | J17: 2 | K17: =IF(ISERROR(L7),"",L7) -> 4.972 | L17: =IF(ISERROR(L8),"",L8) -> 0.009944 | M17: =IF(ISERROR(L4),"",L4) -> 0.9632245 | N17: =IF(ISERROR(L5),"",L5) -> 0.0006459443 | AB17: =B17 -> 2 | AC17: =A17 -> FF38022
A18: FF38022 | B18: 2 | C18: 0.96282795 | D18: 4.972 | E18: 0.005 | F18: =IF(ISBLANK(B18),"",IF(ISNUMBER($K$10),D18*$K$10,E18)) -> 0.009944 | J18: 3 | K18: =IF(ISERROR(M7),"",M7) -> 6.036 | L18: =IF(ISERROR(M8),"",M8) -> 0.012072 | M18: =IF(ISERROR(M4),"",M4) -> 1.178333 | N18: =IF(ISERROR(M5),"",M5) -> 0.00053153008 | AB18: =B18 -> 2 | AC18: =A18 -> FF38022
A19: FF38022 | B19: 2 | C19: 0.96334689 | D19: 4.972 | E19: 0.005 | F19: =IF(ISBLANK(B19),"",IF(ISNUMBER($K$10),D19*$K$10,E19)) -> 0.009944 | J19: 4 | K19: =IF(ISERROR(N7),"",N7) -> 9.007 | L19: =IF(ISERROR(N8),"",N8) -> 0.018014 | M19: =IF(ISERROR(N4),"",N4) -> 1.7726021 | N19: =IF(ISERROR(N5),"",N5) -> 0.00051164668 | AB19: =B19 -> 2 | AC19: =A19 -> FF38022
A20: FF38022 | B20: 2 | C20: 0.96305284 | D20: 4.972 | E20: 0.005 | F20: =IF(ISBLANK(B20),"",IF(ISNUMBER($K$10),D20*$K$10,E20)) -> 0.009944 | J20: 5 | K20: =IF(ISERROR(O7),"",O7) | L20: =IF(ISERROR(O8),"",O8) | M20: =IF(ISERROR(O4),"",O4) | N20: =IF(ISERROR(O5),"",O5) | AB20: =B20 -> 2 | AC20: =A20 -> FF38022
A21: FF38022 | B21: 2 | C21: 0.96379393 | D21: 4.972 | E21: 0.005 | F21: =IF(ISBLANK(B21),"",IF(ISNUMBER($K$10),D21*$K$10,E21)) -> 0.009944 | J21: 6 | K21: =IF(ISERROR(P7),"",P7) | L21: =IF(ISERROR(P8),"",P8) | M21: =IF(ISERROR(P4),"",P4) | N21: =IF(ISERROR(P5),"",P5) | AB21: =B21 -> 2 | AC21: =A21 -> FF38022
A22: FF38022 | B22: 2 | C22: 0.96277818 | D22: 4.972 | E22: 0.005 | F22: =IF(ISBLANK(B22),"",IF(ISNUMBER($K$10),D22*$K$10,E22)) -> 0.009944 | J22: 7 | K22: =IF(ISERROR(Q7),"",Q7) | L22: =IF(ISERROR(Q8),"",Q8) | M22: =IF(ISERROR(Q4),"",Q4) | N22: =IF(ISERROR(Q5),"",Q5) | AB22: =B22 -> 2 | AC22: =A22 -> FF38022
A23: FF38022 | B23: 2 | C23: 0.9628899 | D23: 4.972 | E23: 0.005 | F23: =IF(ISBLANK(B23),"",IF(ISNUMBER($K$10),D23*$K$10,E23)) -> 0.009944 | J23: 8 | K23: =IF(ISERROR(R7),"",R7) | L23: =IF(ISERROR(R8),"",R8) | M23: =IF(ISERROR(R4),"",R4) | N23: =IF(ISERROR(R5),"",R5) | AB23: =B23 -> 2 | AC23: =A23 -> FF38022
A24: FF38022 | B24: 2 | C24: 0.96418397 | D24: 4.972 | E24: 0.005 | F24: =IF(ISBLANK(B24),"",IF(ISNUMBER($K$10),D24*$K$10,E24)) -> 0.009944 | J24: 9 | K24: =IF(ISERROR(S7),"",S7) | L24: =IF(ISERROR(S8),"",S8) | M24: =IF(ISERROR(S4),"",S4) | N24: =IF(ISERROR(S5),"",S5) | AB24: =B24 -> 2 | AC24: =A24 -> FF38022
A25: FF38022 | B25: 2 | C25: 0.96459073 | D25: 4.972 | E25: 0.005 | F25: =IF(ISBLANK(B25),"",IF(ISNUMBER($K$10),D25*$K$10,E25)) -> 0.009944 | J25: 10 | K25: =IF(ISERROR(T7),"",T7) | L25: =IF(ISERROR(T8),"",T8) | M25: =IF(ISERROR(T4),"",T4) | N25: =IF(ISERROR(T5),"",T5) | AB25: =B25 -> 2 | AC25: =A25 -> FF38022
A26: FF18162 | B26: 3 | C26: 1.1777211 | D26: 6.036 | E26: 0.006 | F26: =IF(ISBLANK(B26),"",IF(ISNUMBER($K$10),D26*$K$10,E26)) -> 0.012072 | AB26: =B26 -> 3 | AC26: =A26 -> FF18162
A27: FF18162 | B27: 3 | C27: 1.1775407 | D27: 6.036 | E27: 0.006 | F27: =IF(ISBLANK(B27),"",IF(ISNUMBER($K$10),D27*$K$10,E27)) -> 0.012072 | J27: Note: Cassie originally pulled these from dataset. Putting here for future reference. | AB27: =B27 -> 3 | AC27: =A27 -> FF18162
A28: FF18162 | B28: 3 | C28: 1.1781349 | D28: 6.036 | E28: 0.006 | F28: =IF(ISBLANK(B28),"",IF(ISNUMBER($K$10),D28*$K$10,E28)) -> 0.012072 | J28: CAL016209 | K28: 4 | L28: 1.7627154 | M28: 9.007 | N28: 0.009 | AB28: =B28 -> 3 | AC28: =A28 -> FF18162
A29: FF18162 | B29: 3 | C29: 1.1786594 | D29: 6.036 | E29: 0.006 | F29: =IF(ISBLANK(B29),"",IF(ISNUMBER($K$10),D29*$K$10,E29)) -> 0.012072 | J29: CAL016209 | K29: 4 | L29: 1.769607 | M29: 9.007 | N29: 0.009 | AB29: =B29 -> 3 | AC29: =A29 -> FF18162
A30: FF18162 | B30: 3 | C30: 1.1791339 | D30: 6.036 | E30: 0.006 | F30: =IF(ISBLANK(B30),"",IF(ISNUMBER($K$10),D30*$K$10,E30)) -> 0.012072 | AB30: =B30 -> 3 | AC30: =A30 -> FF18162
A31: FF18162 | B31: 3 | C31: 1.1787881 | D31: 6.036 | E31: 0.006 | F31: =IF(ISBLANK(B31),"",IF(ISNUMBER($K$10),D31*$K$10,E31)) -> 0.012072 | AB31: =B31 -> 3 | AC31: =A31 -> FF18162
A32: FF18162 | B32: 3 | C32: 1.1777319 | D32: 6.036 | E32: 0.006 | F32: =IF(ISBLANK(B32),"",IF(ISNUMBER($K$10),D32*$K$10,E32)) -> 0.012072 | AB32: =B32 -> 3 | AC32: =A32 -> FF18162
A33: FF18162 | B33: 3 | C33: 1.1779672 | D33: 6.036 | E33: 0.006 | F33: =IF(ISBLANK(B33),"",IF(ISNUMBER($K$10),D33*$K$10,E33)) -> 0.012072 | AB33: =B33 -> 3 | AC33: =A33 -> FF18162
A34: FF18162 | B34: 3 | C34: 1.1787918 | D34: 6.036 | E34: 0.006 | F34: =IF(ISBLANK(B34),"",IF(ISNUMBER($K$10),D34*$K$10,E34)) -> 0.012072 | AB34: =B34 -> 3 | AC34: =A34 -> FF18162
A35: FF18162 | B35: 3 | C35: 1.1786316 | D35: 6.036 | E35: 0.006 | F35: =IF(ISBLANK(B35),"",IF(ISNUMBER($K$10),D35*$K$10,E35)) -> 0.012072 | AB35: =B35 -> 3 | AC35: =A35 -> FF18162
A36: FF18162 | B36: 3 | C36: 1.1788286 | D36: 6.036 | E36: 0.006 | F36: =IF(ISBLANK(B36),"",IF(ISNUMBER($K$10),D36*$K$10,E36)) -> 0.012072 | AB36: =B36 -> 3 | AC36: =A36 -> FF18162
A37: FF18162 | B37: 3 | C37: 1.1780668 | D37: 6.036 | E37: 0.006 | F37: =IF(ISBLANK(B37),"",IF(ISNUMBER($K$10),D37*$K$10,E37)) -> 0.012072 | AB37: =B37 -> 3 | AC37: =A37 -> FF18162
A38: CAL016209 | B38: 4 | C38: 1.7721416 | D38: 9.007 | E38: 0.009 | F38: =IF(ISBLANK(B38),"",IF(ISNUMBER($K$10),D38*$K$10,E38)) -> 0.018014 | AB38: =B38 -> 4 | AC38: =A38 -> CAL016209
A39: CAL016209 | B39: 4 | C39: 1.7728179 | D39: 9.007 | E39: 0.009 | F39: =IF(ISBLANK(B39),"",IF(ISNUMBER($K$10),D39*$K$10,E39)) -> 0.018014 | AB39: =B39 -> 4 | AC39: =A39 -> CAL016209
A40: CAL016209 | B40: 4 | C40: 1.7720738 | D40: 9.007 | E40: 0.009 | F40: =IF(ISBLANK(B40),"",IF(ISNUMBER($K$10),D40*$K$10,E40)) -> 0.018014 | AB40: =B40 -> 4 | AC40: =A40 -> CAL016209
...

Sheet Past LS
A1: Past Lot Standards | H1: Additional Lot Standards | L1: From "RCertification" | O1: cov(b0,b1) | P1: cov(b0,b2) | Q1: cov(b1,b2) | W1: Linear | X1: SQRT(($M$3 * M13) ^ 2 + $N$2 ^ 2 + (M12 * $N$3) ^ 2 + (2 * M12 * $O$2))
A2: LS ID | B2: LS# | C2: Ratio | D2: Past Conc | E2: Pred Conc | F2: % Diff | H2: ID | I2: LS# | J2: Ratio | L2: b0 | M2: =RCertification!G48 -> 0.11906918 | N2: =RCertification!H48 -> 0.0190002 | O2: =RCertification!H54*N2*N3 -> -0.00033505946 | P2: =IF(ISNUMBER(M4),RCertification!I54*N2*N4,"") | Q2: =IF(ISNUMBER(M4),RCertification!I55*N3*N4,"") | W2: Quadratic | X2: SQRT(($M$3 + 2 * $M$4 * M12) ^ 2 * M13 ^ 2 + $N$2 ^ 2 + ($N$3 ^ 2 * M12 ^ 2) + ($N$4 ^ 2 * M12 ^ 4) + (2 * M12 * $O$2) + (2 * $P$2 * M12 ^ 2) + (2 * $Q$2* M12 ^ 3))
E3: =IF(ISNUMBER(C3),C3*C3*$M$4+C3*$M$3+$M$2,"") | F3: =IF(ISNUMBER(C3),(D3-E3)/D3,"") | H3: 8-IL-02 | I3: 2 | J3: 1.0006651 | L3: b1 | M3: =RCertification!G49 -> 5.0205063 | N3: =RCertification!H49 -> 0.01837103
E4: =IF(ISNUMBER(C4),C4*C4*$M$4+C4*$M$3+$M$2,"") | F4: =IF(ISNUMBER(C4),(D4-E4)/D4,"") | H4: 8-IL-02 | I4: 2 | J4: 1.0014672 | L4: b2 | M4: =RCertification!G50 | N4: =RCertification!H50 | W4: cov(x,y) = corr.coeff(x,y)*ux*uy
E5: =IF(ISNUMBER(C5),C5*C5*$M$4+C5*$M$3+$M$2,"") | F5: =IF(ISNUMBER(C5),(D5-E5)/D5,"") | H5: 8-IL-02 | I5: 2 | J5: 1.0012223 | W5: https://towardsdatascience.com/covariance-and-correlation-321fdacab168
E6: =IF(ISNUMBER(C6),C6*C6*$M$4+C6*$M$3+$M$2,"") | F6: =IF(ISNUMBER(C6),(D6-E6)/D6,"") | H6: 8-IL-02 | I6: 2 | J6: 1.000802 | L6: Past Lot Standards: LS# = 1, 2, 3,...,N. This numbering is independent from the additional LSs. | W6: https://web.stanford.edu/class/archive/cs/cs109/cs109.1178/lectureHandouts/150-covariance.pdf
E7: =IF(ISNUMBER(C7),C7*C7*$M$4+C7*$M$3+$M$2,"") | F7: =IF(ISNUMBER(C7),(D7-E7)/D7,"") | H7: 8-IL-02 | I7: 2 | J7: 1.000434 | L7: Average Conc for Past LS
E8: =IF(ISNUMBER(C8),C8*C8*$M$4+C8*$M$3+$M$2,"") | F8: =IF(ISNUMBER(C8),(D8-E8)/D8,"") | H8: 8-IL-02 | I8: 2 | J8: 1.0007153
E9: =IF(ISNUMBER(C9),C9*C9*$M$4+C9*$M$3+$M$2,"") | F9: =IF(ISNUMBER(C9),(D9-E9)/D9,"") | H9: 8-IL-02 | I9: 2 | J9: 1.0019565 | M9: LS# | N9: LS# | O9: LS# | P9: LS# | Q9: LS# | R9: LS# | S9: LS# | T9: LS#
E10: =IF(ISNUMBER(C10),C10*C10*$M$4+C10*$M$3+$M$2,"") | F10: =IF(ISNUMBER(C10),(D10-E10)/D10,"") | H10: 8-IL-02 | I10: 2 | J10: 1.0011869 | M10: 1 | N10: 2 | O10: 3 | P10: 4 | Q10: 5 | R10: 6 | S10: 7 | T10: 8
E11: =IF(ISNUMBER(C11),C11*C11*$M$4+C11*$M$3+$M$2,"") | F11: =IF(ISNUMBER(C11),(D11-E11)/D11,"") | H11: 8-IL-02 | I11: 2 | J11: 1.0010565 | L11: Past Conc | M11: =DAVERAGE($A$2:$F$100,"Past Conc",M9:M10) -> #DIV/0! | N11: =DAVERAGE($A$2:$F$100,"Past Conc",N9:N10) -> #DIV/0! | O11: =DAVERAGE($A$2:$F$100,"Past Conc",O9:O10) -> #DIV/0! | P11: =DAVERAGE($A$2:$F$100,"Past Conc",P9:P10) -> #DIV/0! | Q11: =DAVERAGE($A$2:$F$100,"Past Conc",Q9:Q10) -> #DIV/0! | R11: =DAVERAGE($A$2:$F$100,"Past Conc",R9:R10) -> #DIV/0! | S11: =DAVERAGE($A$2:$F$100,"Past Conc",S9:S10) -> #DIV/0! | T11: =DAVERAGE($A$2:$F$100,"Past Conc",T9:T10) -> #DIV/0!
E12: =IF(ISNUMBER(C12),C12*C12*$M$4+C12*$M$3+$M$2,"") | F12: =IF(ISNUMBER(C12),(D12-E12)/D12,"") | H12: 8-IL-02 | I12: 2 | J12: 1.0004597 | L12: ratio | M12: =DAVERAGE($A$2:$F$100,"Ratio",M9:M10) -> #DIV/0! | N12: =DAVERAGE($A$2:$F$100,"Ratio",N9:N10) -> #DIV/0! | O12: =DAVERAGE($A$2:$F$100,"Ratio",O9:O10) -> #DIV/0! | P12: =DAVERAGE($A$2:$F$100,"Ratio",P9:P10) -> #DIV/0! | Q12: =DAVERAGE($A$2:$F$100,"Ratio",Q9:Q10) -> #DIV/0! | R12: =DAVERAGE($A$2:$F$100,"Ratio",R9:R10) -> #DIV/0! | S12: =DAVERAGE($A$2:$F$100,"Ratio",S9:S10) -> #DIV/0! | T12: =DAVERAGE($A$2:$F$100,"Ratio",T9:T10) -> #DIV/0!
E13: =IF(ISNUMBER(C13),C13*C13*$M$4+C13*$M$3+$M$2,"") | F13: =IF(ISNUMBER(C13),(D13-E13)/D13,"") | H13: 8-IL-02 | I13: 2 | J13: 1.0009921 | L13: uratio | M13: =DSTDEV($A$2:$F$100,"Ratio",M9:M10)/SQRT(DCOUNT($A$2:$F$100,"Ratio",M9:M10)) -> #DIV/0! | N13: =DSTDEV($A$2:$F$100,"Ratio",N9:N10)/SQRT(DCOUNT($A$2:$F$100,"Ratio",N9:N10)) -> #DIV/0! | O13: =DSTDEV($A$2:$F$100,"Ratio",O9:O10)/SQRT(DCOUNT($A$2:$F$100,"Ratio",O9:O10)) -> #DIV/0! | P13: =DSTDEV($A$2:$F$100,"Ratio",P9:P10)/SQRT(DCOUNT($A$2:$F$100,"Ratio",P9:P10)) -> #DIV/0! | Q13: =DSTDEV($A$2:$F$100,"Ratio",Q9:Q10)/SQRT(DCOUNT($A$2:$F$100,"Ratio",Q9:Q10)) -> #DIV/0! | R13: =DSTDEV($A$2:$F$100,"Ratio",R9:R10)/SQRT(DCOUNT($A$2:$F$100,"Ratio",R9:R10)) -> #DIV/0! | S13: =DSTDEV($A$2:$F$100,"Ratio",S9:S10)/SQRT(DCOUNT($A$2:$F$100,"Ratio",S9:S10)) -> #DIV/0! | T13: =DSTDEV($A$2:$F$100,"Ratio",T9:T10)/SQRT(DCOUNT($A$2:$F$100,"Ratio",T9:T10)) -> #DIV/0!
E14: =IF(ISNUMBER(C14),C14*C14*$M$4+C14*$M$3+$M$2,"") | F14: =IF(ISNUMBER(C14),(D14-E14)/D14,"") | H14: 8-IL-02 | I14: 2 | J14: 1.0009987 | L14: Pred Conc | M14: =M12 ^ 2 * $M$4 + M12 * $M$3 + $M$2 -> #DIV/0! | N14: =N12 ^ 2 * $M$4 + N12 * $M$3 + $M$2 -> #DIV/0! | O14: =O12 ^ 2 * $M$4 + O12 * $M$3 + $M$2 -> #DIV/0! | P14: =P12 ^ 2 * $M$4 + P12 * $M$3 + $M$2 -> #DIV/0! | Q14: =Q12 ^ 2 * $M$4 + Q12 * $M$3 + $M$2 -> #DIV/0! | R14: =R12 ^ 2 * $M$4 + R12 * $M$3 + $M$2 -> #DIV/0! | S14: =S12 ^ 2 * $M$4 + S12 * $M$3 + $M$2 -> #DIV/0! | T14: =T12 ^ 2 * $M$4 + T12 * $M$3 + $M$2 -> #DIV/0!
E15: =IF(ISNUMBER(C15),C15*C15*$M$4+C15*$M$3+$M$2,"") | F15: =IF(ISNUMBER(C15),(D15-E15)/D15,"") | H15: 8-IL-03 | I15: 3 | J15: 0.99712063 | L15: Pred unc | M15: =SQRT(($M$3 + 2 * $M$4 * M12) ^ 2 * M13 ^ 2 + $N$2 ^ 2 + ($N$3 ^ 2 * M12 ^ 2) + ($N$4 ^ 2 * M12 ^ 4) + (2 * M12 * $O$2) + (2 * $P$2 * M12 ^ 2) + (2 * $Q$2* M12 ^ 3)) -> #VALUE! | N15: =SQRT(($M$3 + 2 * $M$4 * N12) ^ 2 * N13 ^ 2 + $N$2 ^ 2 + ($N$3 ^ 2 * N12 ^ 2) + ($N$4 ^ 2 * N12 ^ 4) + (2 * N12 * $O$2) + (2 * $P$2 * N12 ^ 2) + (2 * $Q$2* N12 ^ 3)) -> #VALUE! | O15: =SQRT(($M$3 + 2 * $M$4 * O12) ^ 2 * O13 ^ 2 + $N$2 ^ 2 + ($N$3 ^ 2 * O12 ^ 2) + ($N$4 ^ 2 * O12 ^ 4) + (2 * O12 * $O$2) + (2 * $P$2 * O12 ^ 2) + (2 * $Q$2* O12 ^ 3)) -> #VALUE! | P15: =SQRT(($M$3 + 2 * $M$4 * P12) ^ 2 * P13 ^ 2 + $N$2 ^ 2 + ($N$3 ^ 2 * P12 ^ 2) + ($N$4 ^ 2 * P12 ^ 4) + (2 * P12 * $O$2) + (2 * $P$2 * P12 ^ 2) + (2 * $Q$2* P12 ^ 3)) -> #VALUE! | Q15: =SQRT(($M$3 + 2 * $M$4 * Q12) ^ 2 * Q13 ^ 2 + $N$2 ^ 2 + ($N$3 ^ 2 * Q12 ^ 2) + ($N$4 ^ 2 * Q12 ^ 4) + (2 * Q12 * $O$2) + (2 * $P$2 * Q12 ^ 2) + (2 * $Q$2* Q12 ^ 3)) -> #VALUE! | R15: =SQRT(($M$3 + 2 * $M$4 * R12) ^ 2 * R13 ^ 2 + $N$2 ^ 2 + ($N$3 ^ 2 * R12 ^ 2) + ($N$4 ^ 2 * R12 ^ 4) + (2 * R12 * $O$2) + (2 * $P$2 * R12 ^ 2) + (2 * $Q$2* R12 ^ 3)) -> #VALUE! | S15: =SQRT(($M$3 + 2 * $M$4 * S12) ^ 2 * S13 ^ 2 + $N$2 ^ 2 + ($N$3 ^ 2 * S12 ^ 2) + ($N$4 ^ 2 * S12 ^ 4) + (2 * S12 * $O$2) + (2 * $P$2 * S12 ^ 2) + (2 * $Q$2* S12 ^ 3)) -> #VALUE! | T15: =SQRT(($M$3 + 2 * $M$4 * T12) ^ 2 * T13 ^ 2 + $N$2 ^ 2 + ($N$3 ^ 2 * T12 ^ 2) + ($N$4 ^ 2 * T12 ^ 4) + (2 * T12 * $O$2) + (2 * $P$2 * T12 ^ 2) + (2 * $Q$2* T12 ^ 3)) -> #VALUE!
E16: =IF(ISNUMBER(C16),C16*C16*$M$4+C16*$M$3+$M$2,"") | F16: =IF(ISNUMBER(C16),(D16-E16)/D16,"") | H16: 8-IL-03 | I16: 3 | J16: 0.9961033 | L16: % Diff | M16: =(M11-M14)/M11 -> #DIV/0! | N16: =(N11-N14)/N11 -> #DIV/0! | O16: =(O11-O14)/O11 -> #DIV/0! | P16: =(P11-P14)/P11 -> #DIV/0! | Q16: =(Q11-Q14)/Q11 -> #DIV/0! | R16: =(R11-R14)/R11 -> #DIV/0! | S16: =(S11-S14)/S11 -> #DIV/0! | T16: =(T11-T14)/T11 -> #DIV/0!
E17: =IF(ISNUMBER(C17),C17*C17*$M$4+C17*$M$3+$M$2,"") | F17: =IF(ISNUMBER(C17),(D17-E17)/D17,"") | H17: 8-IL-03 | I17: 3 | J17: 0.99635502 | L17: Abs Value | M17: =IF(ISERROR(M16),"",ABS(M16)) | N17: =IF(ISERROR(N16),"",ABS(N16)) | O17: =IF(ISERROR(O16),"",ABS(O16)) | P17: =IF(ISERROR(P16),"",ABS(P16)) | Q17: =IF(ISERROR(Q16),"",ABS(Q16)) | R17: =IF(ISERROR(R16),"",ABS(R16)) | S17: =IF(ISERROR(S16),"",ABS(S16)) | T17: =IF(ISERROR(T16),"",ABS(T16))
E18: =IF(ISNUMBER(C18),C18*C18*$M$4+C18*$M$3+$M$2,"") | F18: =IF(ISNUMBER(C18),(D18-E18)/D18,"") | H18: 8-IL-03 | I18: 3 | J18: 0.99673517 | L18: Avg % Diff | N18: =AVERAGE(M17:T17) -> #DIV/0!
E19: =IF(ISNUMBER(C19),C19*C19*$M$4+C19*$M$3+$M$2,"") | F19: =IF(ISNUMBER(C19),(D19-E19)/D19,"") | H19: 8-IL-03 | I19: 3 | J19: 0.99683258
E20: =IF(ISNUMBER(C20),C20*C20*$M$4+C20*$M$3+$M$2,"") | F20: =IF(ISNUMBER(C20),(D20-E20)/D20,"") | H20: 8-IL-03 | I20: 3 | J20: 0.99662874 | L20: Additional Lot standards: LS# = 2, 3, 4. LS# 1 is always control LS used.
E21: =IF(ISNUMBER(C21),C21*C21*$M$4+C21*$M$3+$M$2,"") | F21: =IF(ISNUMBER(C21),(D21-E21)/D21,"") | H21: 8-IL-03 | I21: 3 | J21: 0.99766816 | L21: Additional Lot Standards
E22: =IF(ISNUMBER(C22),C22*C22*$M$4+C22*$M$3+$M$2,"") | F22: =IF(ISNUMBER(C22),(D22-E22)/D22,"") | H22: 8-IL-03 | I22: 3 | J22: 0.99681283
E23: =IF(ISNUMBER(C23),C23*C23*$M$4+C23*$M$3+$M$2,"") | F23: =IF(ISNUMBER(C23),(D23-E23)/D23,"") | H23: 8-IL-03 | I23: 3 | J23: 0.99761996 | M23: LS# | N23: LS# | O23: LS#
E24: =IF(ISNUMBER(C24),C24*C24*$M$4+C24*$M$3+$M$2,"") | F24: =IF(ISNUMBER(C24),(D24-E24)/D24,"") | H24: 8-IL-03 | I24: 3 | J24: 0.99678597 | M24: 2 | N24: 3 | O24: 4
E25: =IF(ISNUMBER(C25),C25*C25*$M$4+C25*$M$3+$M$2,"") | F25: =IF(ISNUMBER(C25),(D25-E25)/D25,"") | H25: 8-IL-03 | I25: 3 | J25: 0.99710962 | L25: Ratio | M25: =DAVERAGE($H$2:$J$50,3,M$23:M$24) -> 1.0009964 | N25: =DAVERAGE($H$2:$J$50,3,N$23:N$24) -> 0.99695907 | O25: =DAVERAGE($H$2:$J$50,3,O$23:O$24) -> 1.002149
E26: =IF(ISNUMBER(C26),C26*C26*$M$4+C26*$M$3+$M$2,"") | F26: =IF(ISNUMBER(C26),(D26-E26)/D26,"") | H26: 8-IL-03 | I26: 3 | J26: 0.99773682 | L26: uncert | M26: =DSTDEV($H$2:$J$50,3,M$23:M$24)/SQRT(DCOUNT($H$2:$J$50,3,M$23:M$24)) -> 0.00012508204 | N26: =DSTDEV($H$2:$J$50,3,N$23:N$24)/SQRT(DCOUNT($H$2:$J$50,3,N$23:N$24)) -> 0.0001486574 | O26: =DSTDEV($H$2:$J$50,3,O$23:O$24)/SQRT(DCOUNT($H$2:$J$50,3,O$23:O$24)) -> 0.00012365777
E27: =IF(ISNUMBER(C27),C27*C27*$M$4+C27*$M$3+$M$2,"") | F27: =IF(ISNUMBER(C27),(D27-E27)/D27,"") | H27: 8-IL-04 | I27: 4 | J27: 1.0024186
E28: =IF(ISNUMBER(C28),C28*C28*$M$4+C28*$M$3+$M$2,"") | F28: =IF(ISNUMBER(C28),(D28-E28)/D28,"") | H28: 8-IL-04 | I28: 4 | J28: 1.001385 | M28: Number of points = | N28: =COUNT(J3:J50) -> 36
E29: =IF(ISNUMBER(C29),C29*C29*$M$4+C29*$M$3+$M$2,"") | F29: =IF(ISNUMBER(C29),(D29-E29)/D29,"") | H29: 8-IL-04 | I29: 4 | J29: 1.0020327 | L29: *Assigned values for Additional LSs are listed in the RCertification tab (Column A Row 72)*
E30: =IF(ISNUMBER(C30),C30*C30*$M$4+C30*$M$3+$M$2,"") | F30: =IF(ISNUMBER(C30),(D30-E30)/D30,"") | H30: 8-IL-04 | I30: 4 | J30: 1.0019015
E31: =IF(ISNUMBER(C31),C31*C31*$M$4+C31*$M$3+$M$2,"") | F31: =IF(ISNUMBER(C31),(D31-E31)/D31,"") | H31: 8-IL-04 | I31: 4 | J31: 1.0022217
E32: =IF(ISNUMBER(C32),C32*C32*$M$4+C32*$M$3+$M$2,"") | F32: =IF(ISNUMBER(C32),(D32-E32)/D32,"") | H32: 8-IL-04 | I32: 4 | J32: 1.0018019
E33: =IF(ISNUMBER(C33),C33*C33*$M$4+C33*$M$3+$M$2,"") | F33: =IF(ISNUMBER(C33),(D33-E33)/D33,"") | H33: 8-IL-04 | I33: 4 | J33: 1.0023235
E34: =IF(ISNUMBER(C34),C34*C34*$M$4+C34*$M$3+$M$2,"") | F34: =IF(ISNUMBER(C34),(D34-E34)/D34,"") | H34: 8-IL-04 | I34: 4 | J34: 1.0020339
E35: =IF(ISNUMBER(C35),C35*C35*$M$4+C35*$M$3+$M$2,"") | F35: =IF(ISNUMBER(C35),(D35-E35)/D35,"") | H35: 8-IL-04 | I35: 4 | J35: 1.0029232
E36: =IF(ISNUMBER(C36),C36*C36*$M$4+C36*$M$3+$M$2,"") | F36: =IF(ISNUMBER(C36),(D36-E36)/D36,"") | H36: 8-IL-04 | I36: 4 | J36: 1.0021539
E37: =IF(ISNUMBER(C37),C37*C37*$M$4+C37*$M$3+$M$2,"") | F37: =IF(ISNUMBER(C37),(D37-E37)/D37,"") | H37: 8-IL-04 | I37: 4 | J37: 1.0027833
E38: =IF(ISNUMBER(C38),C38*C38*$M$4+C38*$M$3+$M$2,"") | F38: =IF(ISNUMBER(C38),(D38-E38)/D38,"") | H38: 8-IL-04 | I38: 4 | J38: 1.0018084
E39: =IF(ISNUMBER(C39),C39*C39*$M$4+C39*$M$3+$M$2,"") | F39: =IF(ISNUMBER(C39),(D39-E39)/D39,"")
E40: =IF(ISNUMBER(C40),C40*C40*$M$4+C40*$M$3+$M$2,"") | F40: =IF(ISNUMBER(C40),(D40-E40)/D40,"")
...

Sheet Ratio Analysis
A1: Step 1. | B1: UNGROUPED MODEL (ZERO FACTORS) | R1: cylinder | T1: Standard | V1: vendor | X1: Random Effects | AD1: Fixed Effects Intercept
O2: standard | P2: cylinder | Q2: vendor | R2: names | S2: No | T2: names | U2: No | V2: names | W2: No | X2: Groups | Y2: Name | Z2: Variance | AA2: Std Dev | AB2: Relative | AC2: No | AD2: Estimate | AE2: Std Error | AF2: t value
B3: Step 1.1 | C3: =DAVERAGE(RatioData,"Ratio",H4:H5) -> 0.9805811 | D3: = | E3: Mean of all ratios | H3: Criteria for lookup | O3: StandardID | P3: SampleID | R3: 48-I-05 | S3: 8 | T3: CAL016209 | U3: 10 | X3: LSSet:BreakSet | Y3: (Intercept) | Z3: 3.9383704e-16 | AA3: 1.9845328e-08 | AB3: 7.1893345e-12 | AC3: 242 | AD3: 0.98054292 | AE3: 0.0010138743 | AF3: 967.1247
C4: =DSTDEV(RatioData,"Ratio",H4:H5) -> 0.0064671357 | D4: = | E4: s, Standard deviation of all ratios | H4: SampleNo | O4: StandardNo | P4: SampleNo | R4: 48-I-06 | S4: 8 | T4: FF18162 | U4: 12 | X4: SampleID | Y4: (Intercept) | Z4: 4.6053637e-05 | AA4: 0.006786283 | AB4: 0.84069036 | AC4: 59
C5: =DCOUNT(RatioData,"Ratio",H4:H5) -> 472 | D5: = | E5: n, Number of ratios | O5: SRatio | P5: Ratio | R5: 48-I-07 | S5: 8 | T5: FF38000 | U5: 12 | X5: BreakSet | Y5: (Intercept) | Z5: 7.4410763e-06 | AA5: 0.0027278336 | AB5: 0.13583381 | AC5: 31
B6: Step 1.2 | C6: =C4/SQRT(C5) -> 0.00029767405 | D6: = | E6: s/sqrt(n), Standard uncertainty | O6: SConc | P6: LSSet | R6: 48-I-08 | S6: 8 | T6: FF38022 | U6: 12 | X6: Day | Y6: (Intercept) | Z6: 6.8785804e-15 | AA6: 8.2937207e-08 | AB6: 1.2556568e-10 | AC6: 22
B7: Step 1.3 | C7: =C5-1 -> 471 | D7: = | E7: degrees of freedom | O7: Sunc | P7: BreakSet | R7: 48-I-09 | S7: 8 | X7: Port | Y7: (Intercept) | Z7: 2.0831349e-08 | AA7: 0.00014433069 | AB7: 0.00038026778 | AC7: 5
O8: Suncert | P8: Day | R8: 48-I-10 | S8: 8 | X8: Residual | Z8: 1.2651917e-06 | AA8: 0.0011248074 | AB8: 0.023095559
P9: Port | R9: 48-I-11 | S9: 8
A10: Step 2. | B10: SINGLE FACTOR MODELS | P10: ValueG | R10: 48-I-12 | S10: 8
P11: Test | R11: 48-I-14 | S11: 8
R12: 48-I-15 | S12: 8
A13: Step 2.1 | B13: Grouping factor = LS-Set | R13: 48-I-16 | S13: 8
B14: SAME AS UNGROUPED MODEL (LS BRACKETS EACH RUN) | R14: 48-I-17 | S14: 8
R15: 48-I-18 | S15: 8
R16: 48-I-19 | S16: 8
R17: 48-I-20 | S17: 8
R18: 48-I-21 | S18: 8
R19: 48-I-22 | S19: 8
R20: 48-I-23 | S20: 8
R21: 48-I-24 | S21: 8
R22: 48-I-25 | S22: 8
B23: Mean of means | C23: =C3 -> 0.9805811 | R23: 48-I-26 | S23: 8
B24: s, standard deviation | C24: =C4 -> 0.0064671357 | R24: 48-I-27 | S24: 8
B25: n, number of means | C25: =C5 -> 472 | R25: 48-I-28 | S25: 8
B26: s/sqrt(n), Std. Unc. | C26: =C24/SQRT(C25) -> 0.00029767405 | R26: 48-I-29 | S26: 8
B27: degrees of freedom | C27: =C25-1 -> 471 | R27: 48-I-30 | S27: 8
R28: 48-I-31 | S28: 8
R29: 48-I-32 | S29: 8
A30: Step 2.1 | B30: Grouping factor = Cylinder ID | R30: 48-I-33 | S30: 8
R31: 48-I-34 | S31: 8
B32: SampleNo | C32: SampleNo | D32: SampleNo | E32: SampleNo | F32: SampleNo | G32: SampleNo | H32: SampleNo | I32: SampleNo | J32: SampleNo | K32: SampleNo | L32: SampleNo | M32: SampleNo | N32: SampleNo | R32: 48-I-35 | S32: 8
B33: 1 | C33: =B33+1 -> 2 | D33: =C33+1 -> 3 | E33: =D33+1 -> 4 | F33: =E33+1 -> 5 | G33: =F33+1 -> 6 | H33: =G33+1 -> 7 | I33: =H33+1 -> 8 | J33: =I33+1 -> 9 | ... N33: =M33+1 -> 13 | R33: 48-I-36 | S33: 8
B34: =DAVERAGE(RatioData,"Ratio",B32:B33) -> #DIV/0! | C34: =DAVERAGE(RatioData,"Ratio",C32:C33) -> #DIV/0! | D34: =DAVERAGE(RatioData,"Ratio",D32:D33) -> #DIV/0! | E34: =DAVERAGE(RatioData,"Ratio",E32:E33) -> #DIV/0! | F34: =DAVERAGE(RatioData,"Ratio",F32:F33) -> 0.9811735 | G34: =DAVERAGE(RatioData,"Ratio",G32:G33) -> 0.97371898 | H34: =DAVERAGE(RatioData,"Ratio",H32:H33) -> 0.98641549 | I34: =DAVERAGE(RatioData,"Ratio",I32:I33) -> 0.96610189 | ... N34: =DAVERAGE(RatioData,"Ratio",N32:N33) -> #DIV/0! | R34: 48-I-37 | S34: 8
B35: =DSTDEV(RatioData,"Ratio",B32:B33)/B34 -> #DIV/0! | C35: =DSTDEV(RatioData,"Ratio",C32:C33)/C34 -> #DIV/0! | D35: =DSTDEV(RatioData,"Ratio",D32:D33)/D34 -> #DIV/0! | E35: =DSTDEV(RatioData,"Ratio",E32:E33)/E34 -> #DIV/0! | F35: =DSTDEV(RatioData,"Ratio",F32:F33)/F34 -> 0.001738129 | G35: =DSTDEV(RatioData,"Ratio",G32:G33)/G34 -> 0.00036673855 | H35: =DSTDEV(RatioData,"Ratio",H32:H33)/H34 -> 0.00077256985 | I35: =DSTDEV(RatioData,"Ratio",I32:I33)/I34 -> 0.0017259063 | ... N35: =DSTDEV(RatioData,"Ratio",N32:N33)/N34 -> #DIV/0! | R35: 48-I-38 | S35: 8
B36: =IF(ISNUMBER(B34),B34,"") | C36: =IF(ISNUMBER(C34),C34,"") | D36: =IF(ISNUMBER(D34),D34,"") | E36: =IF(ISNUMBER(E34),E34,"") | F36: =IF(ISNUMBER(F34),F34,"") -> 0.9811735 | G36: =IF(ISNUMBER(G34),G34,"") -> 0.97371898 | H36: =IF(ISNUMBER(H34),H34,"") -> 0.98641549 | I36: =IF(ISNUMBER(I34),I34,"") -> 0.96610189 | ... N36: =IF(ISNUMBER(N34),N34,"") | R36: 48-I-39 | S36: 8
R37: 48-I-40 | S37: 8
B38: SampleNo | C38: SampleNo | D38: SampleNo | E38: SampleNo | F38: SampleNo | G38: SampleNo | H38: SampleNo | I38: SampleNo | J38: SampleNo | K38: SampleNo | L38: SampleNo | M38: SampleNo | N38: SampleNo | R38: 48-I-41 | S38: 8
B39: 14 | C39: =B39+1 -> 15 | D39: =C39+1 -> 16 | E39: =D39+1 -> 17 | F39: =E39+1 -> 18 | G39: =F39+1 -> 19 | H39: =G39+1 -> 20 | I39: =H39+1 -> 21 | J39: =I39+1 -> 22 | ... N39: =M39+1 -> 26 | R39: 48-I-42 | S39: 8
B40: =DAVERAGE(RatioData,"Ratio",B38:B39) -> 0.98099175 | C40: =DAVERAGE(RatioData,"Ratio",C38:C39) -> 0.97626829 | D40: =DAVERAGE(RatioData,"Ratio",D38:D39) -> 0.98129877 | E40: =DAVERAGE(RatioData,"Ratio",E38:E39) -> 0.97746146 | F40: =DAVERAGE(RatioData,"Ratio",F38:F39) -> 0.9828031 | G40: =DAVERAGE(RatioData,"Ratio",G38:G39) -> 0.98700032 | H40: =DAVERAGE(RatioData,"Ratio",H38:H39) -> 0.98038463 | I40: =DAVERAGE(RatioData,"Ratio",I38:I39) -> 0.98702944 | ... N40: =DAVERAGE(RatioData,"Ratio",N38:N39) -> 0.9863956 | R40: 48-I-43 | S40: 8
...

Sheet Std Analysis
A1: Step 5. | B1: ANALYSIS OF CALIBRATION DATA | L1: 1 | M1: 0 | N1: <--Assumed LS Ratio and uncert | T1: Ratio | U1: StdErr | V1: Conc | W1: StdErr
H2: Regression Output | J2: Formula | L2: =($L$1-Intercept)/Slope -> 5.1410423 | N2: <--Concentration of LS from OLS | S2: 1 | T2: ='Standards Data'!M16 -> 0.77623406 | U2: ='Standards Data'!N16 -> 0.00040122745 | V2: ='Standards Data'!K16 -> 4.0069 | W2: ='Standards Data'!L16 -> 0.0080138
B3: Number of measurents: | D3: =COUNT(SRatio) -> 46 | H3: slope, m | I3: =B27 -> 0.19962526 | J3: =B27 | S3: 2 | T3: ='Standards Data'!M17 -> 0.9632245 | U3: ='Standards Data'!N17 -> 0.0006459443 | V3: ='Standards Data'!K17 -> 4.972 | W3: ='Standards Data'!L17 -> 0.009944
B4: Average Concentration: | D4: =AVERAGE(SConc) -> 5.8749739 | H4: u(m) | I4: =C27 -> 0.00018008495 | J4: =C27 | L4: 1 | N4: <--EIV Degree | S4: 3 | T4: ='Standards Data'!M18 -> 1.178333 | U4: ='Standards Data'!N18 -> 0.00053153008 | V4: ='Standards Data'!K18 -> 6.036 | W4: ='Standards Data'!L18 -> 0.012072
H5: intercept, b | I5: =B26 -> -0.026281922 | J5: =B26 | L5: =V36 -> 5.1393653 | M5: =W36 -> 0.0054762916 | N5: <--Concentration From ISO6143 | S5: 4 | T5: ='Standards Data'!M19 -> 1.7726021 | U5: ='Standards Data'!N19 -> 0.00051164668 | V5: ='Standards Data'!K19 -> 9.007 | W5: ='Standards Data'!L19 -> 0.018014
A6: Step 5.1 | B6: Regression output, below | E6: Do Regression Below | H6: u(b) | I6: =C26 -> 0.0011068657 | J6: =C26 | L6: =L5*MeanRatio -> 5.0395645 | M6: =SQRT(SUMSQ(L6*SQRT(SUMSQ(M5/L5,StdUnc/MeanRatio)),'Certified Value'!E30)) -> 0.0068194761 | N6: <--ISO6143 Lot Conc and uncertainty | S6: 5 | T6: ='Standards Data'!M20 | U6: ='Standards Data'!N20 | V6: ='Standards Data'!K20 | W6: ='Standards Data'!L20
E7: X=Concentration of Standards | H7: d.f. | I7: =B22 -> 44 | J7: =B22 | N7: (from ratio, LS conc, and LS bias uncerts) | S7: 6 | T7: ='Standards Data'!M21 | U7: ='Standards Data'!N21 | V7: ='Standards Data'!K21 | W7: ='Standards Data'!L21
E8: Y=Ratios | H8: u(m,b) | I8: =- D4*C27^2 -> -1.9052886e-07 | J8: = - D4*C27^2 | L8: 5.1410538 | M8: 0.0032141641 | N8: <--Monte Carlo estimate | S8: 7 | T8: ='Standards Data'!M22 | U8: ='Standards Data'!N22 | V8: ='Standards Data'!K22 | W8: ='Standards Data'!L22
E9: Output=A10 | L9: 5.0084643 | M9: 0.012050121 | N9: <--Monte Carlo Slope | S9: 8 | T9: ='Standards Data'!M23 | U9: ='Standards Data'!N23 | V9: ='Standards Data'!K23 | W9: ='Standards Data'!L23
A10: SUMMARY OUTPUT | L10: 0.13258944 | M10: 0.012703591 | N10: <--Monte Carlo Intercept | S10: 9 | T10: ='Standards Data'!M24 | U10: ='Standards Data'!N24 | V10: ='Standards Data'!K24 | W10: ='Standards Data'!L24
M11: (all k = 1) | S11: 10 | T11: ='Standards Data'!M25 | U11: ='Standards Data'!N25 | V11: ='Standards Data'!K25 | W11: ='Standards Data'!L25
A12: Regression Statistics | R12: Primary LS | T12: =L1 -> 1 | U12: =M1 -> 0
A13: Multiple R | B13: 0.9999821 | R13: Additional LS | T13: =IF(ISERROR('Past LS'!M25),"",'Past LS'!M25) -> 1.0009964 | U13: =IF(ISERROR('Past LS'!M26),"",'Past LS'!M26) -> 0.00012508204
A14: R Square | B14: 0.99996419 | R14: Additional LS | T14: =IF(ISERROR('Past LS'!N25),"",'Past LS'!N25) -> 0.99695907 | U14: =IF(ISERROR('Past LS'!N26),"",'Past LS'!N26) -> 0.0001486574
A15: Adjusted R Square | B15: 0.99996338 | R15: Additional LS | T15: =IF(ISERROR('Past LS'!O25),"",'Past LS'!O25) -> 1.002149 | U15: =IF(ISERROR('Past LS'!O26),"",'Past LS'!O26) -> 0.00012365777
A16: Standard Error | B16: 0.0022060793
A17: Observations | B17: 46 | R17: Number of stds | T17: =COUNT(T2:T11) -> 4
R18: Number of LS | T18: =COUNT(T12:T15) -> 4
A19: ANOVA
B20: df | C20: SS | D20: MS | E20: F | F20: Significance F
A21: Regression | B21: 1 | C21: 5.9802377 | D21: 5.9802377 | E21: 1228785.8 | F21: 1.8403243e-99
A22: Residual | B22: 44 | C22: 0.00021413859 | D22: 4.866786e-06 | T22: GENLINE - Linear (y=b0+b1*x) | Y22: 20
A23: Total | B23: 45 | C23: 5.9804518 | U23: Value | V23: Std Error
T24: b0 | U24: 0.11912533 | V24: 0.019756837
B25: Coefficients | C25: Standard Error | D25: t Stat | E25: P-value | F25: Lower 95% | G25: Upper 95% | H25: Lower 95.0% | I25: Upper 95.0% | T25: b1 | U25: 5.02024 | V25: 0.019046724
A26: Intercept | B26: -0.026281922 | C26: 0.0011068657 | D26: -23.744453 | E26: 1.0152399e-26 | F26: -0.028512663 | G26: -0.02405118 | H26: -0.028512663 | I26: -0.02405118 | T26: cov(b0,b1) | V26: -0.00036156027
A27: X Variable 1 | B27: 0.19962526 | C27: 0.00018008495 | D27: 1108.5061 | E27: 1.8403243e-99 | F27: 0.19926233 | G27: 0.1999882 | H27: 0.19926233 | I27: 0.1999882 | T27: rms residual error | V27: 1.4688555
T29: X | U29: Y | V29: X-Solution | W29: Y-Solution | X29: uTest
T30: 0.77623406 | U30: 4.0069 | V30: 0.77612627 | W30: 4.0154655 | X30: PASS
A31: RESIDUAL OUTPUT | T31: 0.9632245 | U31: 4.972 | V31: 0.96355491 | W31: 4.9564022 | X31: PASS
T32: 1.178333 | U32: 6.036 | V32: 1.1783456 | W32: 6.0347031 | X32: PASS
A33: Observation | B33: Predicted Y | C33: Residuals | T33: 1.7726021 | U33: 9.007 | V33: 1.7725584 | W33: 9.0177939 | X33: PASS
A34: 1 | B34: 0.77359655 | C34: 0.0028341183 | J34: =D91/B27*SQRT(1/9+1/F92+((I31-H91)^2)/(B27*B27*F91)) -> #DIV/0!
A35: 2 | B35: 0.77359655 | C35: 0.0030667868 | T35: Xin | U35: uXin | V35: Yeval | W35: uYeval
A36: 3 | B36: 0.77359655 | C36: 0.002928848 | S36: =IF(T36=1,"LS# 1",IF(T36="Xin","",IF(ISBLANK(T36),"",IF(T36='Past LS'!$M$25,CONCATENATE('Past LS'!$M$23,," ",'Past LS'!$M$24),IF(T36='Past LS'!$N$25,CONCATENATE('Past LS'!$N$23,," ",'Past LS'!$N$24),IF(T36='Past LS'!$O$25,CONCATENATE('Past LS'!$O$23,," ",'Past LS'!$O$24),"ERROR")))))) -> LS# 1 | T36: 1 | U36: 0 | V36: 5.1393653 | W36: 0.0054762916
A37: 4 | B37: 0.77359655 | C37: 0.0024635812 | S37: =IF(T37=1,"LS# 1",IF(T37="Xin","",IF(ISBLANK(T37),"",IF(T37='Past LS'!$M$25,CONCATENATE('Past LS'!$M$23,," ",'Past LS'!$M$24),IF(T37='Past LS'!$N$25,CONCATENATE('Past LS'!$N$23,," ",'Past LS'!$N$24),IF(T37='Past LS'!$O$25,CONCATENATE('Past LS'!$O$23,," ",'Past LS'!$O$24),"ERROR")))))) -> LS# 2 | T37: 1.0009964 | U37: 0.00012508204 | V37: 5.1443673 | W37: 0.0055124284
A38: 5 | B38: 0.77359655 | C38: 0.0022031825 | S38: =IF(T38=1,"LS# 1",IF(T38="Xin","",IF(ISBLANK(T38),"",IF(T38='Past LS'!$M$25,CONCATENATE('Past LS'!$M$23,," ",'Past LS'!$M$24),IF(T38='Past LS'!$N$25,CONCATENATE('Past LS'!$N$23,," ",'Past LS'!$N$24),IF(T38='Past LS'!$O$25,CONCATENATE('Past LS'!$O$23,," ",'Past LS'!$O$24),"ERROR")))))) -> LS# 3 | T38: 0.99695907 | U38: 0.0001486574 | V38: 5.1240991 | W38: 0.005526543
A39: 6 | B39: 0.77359655 | C39: 0.0031098276 | S39: =IF(T39=1,"LS# 1",IF(T39="Xin","",IF(ISBLANK(T39),"",IF(T39='Past LS'!$M$25,CONCATENATE('Past LS'!$M$23,," ",'Past LS'!$M$24),IF(T39='Past LS'!$N$25,CONCATENATE('Past LS'!$N$23,," ",'Past LS'!$N$24),IF(T39='Past LS'!$O$25,CONCATENATE('Past LS'!$O$23,," ",'Past LS'!$O$24),"ERROR")))))) -> LS# 4 | T39: 1.002149 | U39: 0.00012365777 | V39: 5.1501538 | W39: 0.0055119923
A40: 7 | B40: 0.77359655 | C40: 0.0028315549 | S40: =IF(T40=1,"LS# 1",IF(T40="Xin","",IF(ISBLANK(T40),"",IF(T40='Past LS'!$M$25,CONCATENATE('Past LS'!$M$23,," ",'Past LS'!$M$24),IF(T40='Past LS'!$N$25,CONCATENATE('Past LS'!$N$23,," ",'Past LS'!$N$24),IF(T40='Past LS'!$O$25,CONCATENATE('Past LS'!$O$23,," ",'Past LS'!$O$24),"ERROR"))))))
A41: 8 | B41: 0.77359655 | C41: 0.0023079618 | S41: =IF(T41=1,"LS# 1",IF(T41="Xin","",IF(ISBLANK(T41),"",IF(T41='Past LS'!$M$25,CONCATENATE('Past LS'!$M$23,," ",'Past LS'!$M$24),IF(T41='Past LS'!$N$25,CONCATENATE('Past LS'!$N$23,," ",'Past LS'!$N$24),IF(T41='Past LS'!$O$25,CONCATENATE('Past LS'!$O$23,," ",'Past LS'!$O$24),"ERROR"))))))
...

Sheet Certified Value
A1: Step 6. | B1: KE Memo VALUE
B4: X* = | C4: =(MeanRatio-Intercept)/Slope -> 5.0437655 | D4: ='Ratio Data'!K23 -> ppm
A7: Step 7. | B7: UNCERTAINTY COMPONENT DUE TO CALIBRATION
B9: Table 1. Computation of standard uncertainty component due to calibration.
B10: Source | C10: ci | D10: ui | E10: ciui | F10: 2c1c2u12
B11: Slope, m | C11: =-CertifiedValue/Slope -> -25.266168 | D11: =uslope -> 0.00018008495 | E11: =D11*C11 -> -0.0045500565
B12: Intercept, b | C12: =-1/Slope -> -5.009386 | D12: =uintercept -> 0.0011068657 | E12: =D12*C12 -> -0.0055447177
B13: Cov(m,b) | C13: =2*C11*C12 -> 253.13597 | D13: =umb -> -1.9052886e-07 | F13: =D13*C13 -> -4.8229708e-05
B14: Combined standard uncertainty, u(cal) | E14: =SQRT(SUMSQ(E11,E12)+F13) -> 0.0017936556
A17: Step 8. | B17: UNCERTAINTY OF PRIMARY STANDARDS
A19: Relative std. deviation of Primary Standards, r(PS) = | F19: 0.001
A20: Standard uncertainty (in concentration units), u(PS) = | F20: =F19*CertifiedValue -> 0.0050437655 | G20: %
A23: Step 9. | B23: COMBINED STANDARD UNCERTAINTY
B25: Table 2. Computation of Combined Standard Uncertainty
B26: Source | C26: ci | D26: ui | E26: ciui | F26: d.f. | G26: %rel
B27: Mean ratio, Y* | C27: =1/Slope -> 5.009386 | D27: =StdUnc -> 0.00081789097 | E27: =D27*C27 -> 0.0040971316 | F27: =DegFree -> 58 | G27: =E27/C27 -> 0.00081789097
B28: Calibration | C28: 1 | D28: =E14 -> 0.0017936556 | E28: =D28*C28 -> 0.0017936556 | F28: =Regdf -> 44 | G28: =E28/C27 -> 0.00035805898
B29: Primary Standards | C29: 1 | D29: =F20 -> 0.0050437655 | E29: =D29*C29 -> 0.0050437655 | F29: infinity | G29: =E29/C27 -> 0.001006863
B30: LS Bias | C30: =C27 -> 5.009386 | D30: =IF(ISERROR('Past LS'!N18),0,'Past LS'!N18)/SQRT(3) -> 0 | E30: =D30*C30 -> 0 | G30: =E30/C27 -> 0
B31: Combined standard uncertainty, uc | E31: =SQRT(SUMSQ(E27:E30)) -> 0.0067411614 | F31: =E31^4/(E27^4/F27+E28^4/F28) -> 405.42691 | G31: =E31/C27 -> 0.0013457061
A34: Step 10. | B34: EXPANDED UNCERTAINTY
B36: Table 3. Calculation of Expanded Uncertainty
B37: Combined standard uncertainty, uc | E37: =E31 -> 0.0067411614
B38: Expansion factor, k | E38: =TINV(0.05,F31) -> 1.9658387
B39: Expanded uncertainty, U | E39: =E38*E37 -> 0.013252036
B42: KE Memo Value: | C42: =CertifiedValue -> 5.0437655 | D42: +/- | E42: =E39 -> 0.013252036 | F42: ='Ratio Data'!$K$23 -> ppm | G42: =E42/C42 -> 0.0026274092 | H42: Relative | I42: k= | J42: =E38 -> 1.9658387
B43: Certified Value (R Code): | C43: =RCertification!B48 -> 5.0422566 | D43: +/- | E43: =RCertification!B50 -> 0.064651718 | F43: ='Ratio Data'!$K$23 -> ppm | G43: =E43/C43 -> 0.012821981 | H43: Relative | I43: k= | J43: =RCertification!B52 -> 1.9698476
B44: Lot Standard: | C44: =RCertification!B54 -> 5.1395755 | D44: +/- | E44: =RCertification!B56 -> 0.010500621 | F44: ='Ratio Data'!$K$23 -> ppm | G44: =E44/C44 -> 0.002043091 | H44: Relative

Sheet RCertification
W43: Test = | X43: 0.8
A44: R analysis date: | B44: November 26 2024
B45: =B50/B49 -> 1.9698476 | M45: Cylinder-specific uncertainties
C46: Keith Memo | F46: Analysis Function Coefficients | J46: Genline Values | M46: SRM | P46: Uncert | R46: CI 95 | S46: CI 95 | T46: Relative | U46: Test
C47: Value | D47: Diff | G47: Value | H47: uncert | I47: 95CL | J47: Value | K47: 95CL | M47: Sample | N47: Value | O47: Uncert | P47: 95% CI | Q47: k | R47: Lower | S47: Upper | T47: Uncert | U47: IN/OUT
A48: SRM Value | B48: 5.0422566 | C48: ='Certified Value'!C42 -> 5.0437655 | D48: =(C48-B48)/B48 -> 0.00029924952 | F48: b0 | G48: 0.11906918 | H48: 0.0190002 | I48: =IF(ISNUMBER(G48),$B$52*H48,"") -> 0.037427499 | J48: =IF(ISNUMBER(G48),'Std Analysis'!U24,"") -> 0.11912533 | K48: =IF(ISNUMBER(H48),'Std Analysis'!V24,"") -> 0.019756837 | M48: 48-I-05 | N48: 5.0450383 | O48: 0.0096209334 | P48: 0.017113347 | Q48: 1.7787616 | R48: 5.027925 | S48: 5.0621517 | T48: =IF(OR(ISBLANK(M48),M48=""),"",P48/N48) -> 0.0033921144 | U48: =IF(ISBLANK(M48),"",IF(ABS(N48-$B$48)<=$B$50*$X$43,"IN","OUT")) -> IN | X48: =N48-P48-R48 -> 0 | Y48: =N48+P48 -> 5.0621517 | Z48: =P48/O48 -> 1.7787616
A49: SRM uncertainty | B49: 0.03282067 | C49: ='Certified Value'!E37 -> 0.0067411614 | F49: b1 | G49: 5.0205063 | H49: 0.01837103 | I49: =IF(ISNUMBER(G49),$B$52*H49,"") -> 0.03618813 | J49: =IF(ISNUMBER(G49),'Std Analysis'!U25,"") -> 5.02024 | K49: =IF(ISNUMBER(H49),'Std Analysis'!V25,"") -> 0.019046724 | M49: 48-I-06 | N49: 5.0076102 | O49: 0.0055943285 | P49: 0.010980222 | Q49: 1.9627418 | R49: 4.99663 | S49: 5.0185904 | T49: =IF(OR(ISBLANK(M49),M49=""),"",P49/N49) -> 0.0021927071 | U49: =IF(M49="","",IF(ABS(N49-$B$48)<=$B$50*$X$43,"IN","OUT")) -> IN | X49: =N49-P49-R49 -> 0 | Y49: =N49+P49 -> 5.0185904
A50: SRM 95 % C.L. | B50: 0.064651718 | C50: ='Certified Value'!E39 -> 0.013252036 | F50: b2 | I50: =IF(ISNUMBER(G50),$B$52*H50,"") | J50: =IF(ISNUMBER(G50),'Std Analysis'!U26,"") | K50: =IF(ISNUMBER(H50),'Std Analysis'!V26,"") | M50: 48-I-07 | N50: 5.0713576 | O50: 0.0064175859 | P50: 0.012494124 | Q50: 1.9468573 | R50: 5.0588635 | S50: 5.0838517 | T50: =IF(OR(ISBLANK(M50),M50=""),"",P50/N50) -> 0.0024636645 | U50: =IF(M50="","",IF(ABS(N50-$B$48)<=$B$50*$X$43,"IN","OUT")) -> IN | V50: low pressure | X50: =N50-P50-R50 -> 0 | Y50: =N50+P50 -> 5.0838517
A51: SRM Rel Unc | B51: 0.012821981 | C51: =C50/C48 -> 0.0026274092 | F51: b3 | I51: =IF(ISNUMBER(G51),$B$52*H51,"") | J51: =IF(ISNUMBER(G51),'Std Analysis'!U27,"") | K51: =IF(ISNUMBER(H51),'Std Analysis'!V27,"") | M51: 48-I-08 | N51: 4.9693658 | O51: 0.0094831193 | P51: 0.016858889 | Q51: 1.7777788 | R51: 4.952507 | S51: 4.9862247 | T51: =IF(OR(ISBLANK(M51),M51=""),"",P51/N51) -> 0.0033925634 | U51: =IF(M51="","",IF(ABS(N51-$B$48)<=$B$50*$X$43,"IN","OUT")) -> OUT | V51: outlier | X51: =N51-P51-R51 -> 0 | Y51: =N51+P51 -> 4.9862247
A52: Effective k factor | B52: 1.9698476 | C52: ='Certified Value'!E38 -> 1.9658387 | F52: Correlation Coefficients | M52: 48-I-09 | N52: 5.0255492 | O52: 0.0060175322 | P52: 0.011725265 | Q52: 1.9485171 | R52: 5.013824 | S52: 5.0372745 | T52: =IF(OR(ISBLANK(M52),M52=""),"",P52/N52) -> 0.002333131 | U52: =IF(M52="","",IF(ABS(N52-$B$48)<=$B$50*$X$43,"IN","OUT")) -> IN | X52: =N52-P52-R52 -> 0 | Y52: =N52+P52 -> 5.0372745
A53: uHistorical | G53: b0 | H53: b1 | I53: b2 | J53: b3 | M53: 48-I-10 | N53: 5.0586176 | O53: 0.0072925491 | P53: 0.014035342 | Q53: 1.924614 | R53: 5.0445823 | S53: 5.072653 | T53: =IF(OR(ISBLANK(M53),M53=""),"",P53/N53) -> 0.002774541 | U53: =IF(M53="","",IF(ABS(N53-$B$48)<=$B$50*$X$43,"IN","OUT")) -> IN | X53: =N53-P53-R53 -> 0 | Y53: =N53+P53 -> 5.072653
A54: LS Value | B54: 5.1395755 | C54: ='Std Analysis'!L5 -> 5.1393653 | D54: =(C54-B54)/B54 -> -4.0888174e-05 | F54: b0 | G54: 1 | H54: -0.95990928 | M54: 48-I-11 | N54: 4.9815216 | O54: 0.0060989666 | P54: 0.011875375 | Q54: 1.9471127 | R54: 4.9696463 | S54: 4.993397 | T54: =IF(OR(ISBLANK(M54),M54=""),"",P54/N54) -> 0.0023838851 | U54: =IF(M54="","",IF(ABS(N54-$B$48)<=$B$50*$X$43,"IN","OUT")) -> OUT | V54: low end | X54: =N54-P54-R54 -> 0 | Y54: =N54+P54 -> 4.993397
A55: LS uncertainty | B55: 0.0053276118 | C55: ='Std Analysis'!M5 -> 0.0054762916 | F55: b1 | G55: -0.95990928 | H55: 1 | M55: 48-I-12 | N55: 5.0948058 | O55: 0.021337641 | P55: 0.036617332 | Q55: 1.7160909 | R55: 5.0581885 | S55: 5.1314232 | T55: =IF(OR(ISBLANK(M55),M55=""),"",P55/N55) -> 0.007187189 | U55: =IF(M55="","",IF(ABS(N55-$B$48)<=$B$50*$X$43,"IN","OUT")) -> OUT | V55: high uncert | X55: =N55-P55-R55 -> 0 | Y55: =N55+P55 -> 5.1314232
A56: LS 95 % C.L. | B56: 0.010500621 | C56: =C55*2 -> 0.010952583 | F56: b2 | M56: 48-I-14 | N56: 5.0441258 | O56: 0.011605923 | P56: 0.019525532 | Q56: 1.6823765 | R56: 5.0246003 | S56: 5.0636513 | T56: =IF(OR(ISBLANK(M56),M56=""),"",P56/N56) -> 0.0038709447 | U56: =IF(M56="","",IF(ABS(N56-$B$48)<=$B$50*$X$43,"IN","OUT")) -> IN | W56: =MIN(N48:N49,N52:N54,N56:N84,N86:N88,N90:N93,N95,N97:N101,N103:N106) -> 4.9783678 | X56: =N56-P56-R56 -> 0 | Y56: =N56+P56 -> 5.0636513
A57: LS Rel Unc | B57: 0.002043091 | C57: =C56/C54 -> 0.0021311159 | F57: b3 | M57: 48-I-15 | N57: 5.02041 | O57: 0.0056697231 | P57: 0.011084724 | Q57: 1.9550732 | R57: 5.0093252 | S57: 5.0314947 | T57: =IF(OR(ISBLANK(M57),M57=""),"",P57/N57) -> 0.002207932 | U57: =IF(M57="","",IF(ABS(N57-$B$48)<=$B$50*$X$43,"IN","OUT")) -> IN | W57: =MAX(N48:N49,N52:N54,N56:N84,N86:N88,N90:N93,N95,N97:N101,N103:N106) -> 5.0924224 | X57: =N57-P57-R57 -> 0 | Y57: =N57+P57 -> 5.0314947
M58: 48-I-16 | N58: 5.0456673 | O58: 0.0062656603 | P58: 0.012205742 | Q58: 1.9480376 | R58: 5.0334615 | S58: 5.057873 | T58: =IF(OR(ISBLANK(M58),M58=""),"",P58/N58) -> 0.0024190541 | U58: =IF(M58="","",IF(ABS(N58-$B$48)<=$B$50*$X$43,"IN","OUT")) -> IN | X58: =N58-P58-R58 -> 0 | Y58: =N58+P58 -> 5.057873
A59: Primary Standards | B59: Value | C59: Uncert (k=2) | D59: Predicted | E59: Uncert (k=2) | F59: %diff | G59: Test | H59: Ratio | I59: Uncert | M59: 48-I-17 | N59: 5.0264007 | O59: 0.0059631745 | P59: 0.011667523 | Q59: 1.9565959 | R59: 5.0147332 | S59: 5.0380682 | T59: =IF(OR(ISBLANK(M59),M59=""),"",P59/N59) -> 0.002321248 | U59: =IF(M59="","",IF(ABS(N59-$B$48)<=$B$50*$X$43,"IN","OUT")) -> IN | X59: =N59-P59-R59 -> 0 | Y59: =N59+P59 -> 5.0380682
A60: 1 | B60: 4.0069 | C60: 0.0160276 | D60: 4.0160656 | E60: 0.013293074 | F60: =IF(ISNUMBER(B60),(D60-B60)/B60,"") -> 0.0022874563 | G60: =IF(ISNUMBER(B60),IF(ABS(D60-B60)<2*SQRT(SUMSQ(E60,C60)),"PASS","FAIL"),"") -> PASS | H60: =IF(ISNUMBER(B60),VLOOKUP(B60,'Standards Data'!$K$15:$N$25,3,FALSE),"") -> 0.77623406 | I60: =IF(ISNUMBER(B60),2*VLOOKUP(B60,'Standards Data'!$K$15:$N$25,4,FALSE),"") -> 0.0008024549 | M60: 48-I-18 | N60: 5.0532203 | O60: 0.0078704215 | P60: 0.015471083 | Q60: 1.9657248 | R60: 5.0377492 | S60: 5.0686914 | T60: =IF(OR(ISBLANK(M60),M60=""),"",P60/N60) -> 0.0030616284 | U60: =IF(M60="","",IF(ABS(N60-$B$48)<=$B$50*$X$43,"IN","OUT")) -> IN | X60: =N60-P60-R60 -> 0 | Y60: =N60+P60 -> 5.0686914
